Workbook

Sheet Grenzen
B2: Sparwoche | C2: R2 | D2: 35
C3: R3 | D3: 45
B5: All in woche | C5: R2 | D5: 40
C6: R3 | D6: 55

Sheet VS
A1: Rang | B1: Kommandant | C1: Punkte | D1: Alt | E1: Neu | F1: Change | G1: Ausnahme
A2: 1 | B2: Last Wolf Warrior | C2: 195401816 | D2: =VLOOKUP(B2,TS!$B$2:$C$104,2,0) -> R2 | E2: R3 | F2: =IF(D2<>E2,"Y","N") -> Y
A3: 2 | B3: Smowy | C3: 153789122 | D3: =VLOOKUP(B3,TS!$B$2:$C$104,2,0) -> R4 | E3: R4 | F3: =IF(D3<>E3,"Y","N") -> N
A4: 3 | B4: SNEAKY BUNNY | C4: 146065019 | D4: =VLOOKUP(B4,TS!$B$2:$C$104,2,0) -> R3 | E4: R3 | F4: =IF(D4<>E4,"Y","N") -> N
A5: 4 | B5: Kotor47 | C5: 145958931 | D5: =VLOOKUP(B5,TS!$B$2:$C$104,2,0) -> R3 | E5: R3 | F5: =IF(D5<>E5,"Y","N") -> N
A6: 5 | B6: JSheridan | C6: 143454107 | D6: =VLOOKUP(B6,TS!$B$2:$C$104,2,0) -> R4 | E6: R4 | F6: =IF(D6<>E6,"Y","N") -> N
A7: 6 | B7: Gordon Freimann | C7: 134223756 | D7: =VLOOKUP(B7,TS!$B$2:$C$104,2,0) -> R3 | E7: R3 | F7: =IF(D7<>E7,"Y","N") -> N
A8: 7 | B8: Svela17 | C8: 131922308 | D8: =VLOOKUP(B8,TS!$B$2:$C$104,2,0) -> R3 | E8: R3 | F8: =IF(D8<>E8,"Y","N") -> N
A9: 8 | B9: supi pupi | C9: 128250646 | D9: =VLOOKUP(B9,TS!$B$2:$C$104,2,0) -> R4 | E9: R4 | F9: =IF(D9<>E9,"Y","N") -> N
A10: 9 | B10: Haulsen | C10: 126620882 | D10: =VLOOKUP(B10,TS!$B$2:$C$104,2,0) -> R3 | E10: R3 | F10: =IF(D10<>E10,"Y","N") -> N
A11: 10 | B11: Giorgiotown | C11: 126315800 | D11: =VLOOKUP(B11,TS!$B$2:$C$104,2,0) -> R3 | E11: R3 | F11: =IF(D11<>E11,"Y","N") -> N
A12: 11 | B12: Baba Basti | C12: 125389607 | D12: =VLOOKUP(B12,TS!$B$2:$C$104,2,0) -> R3 | E12: R3 | F12: =IF(D12<>E12,"Y","N") -> N
A13: 12 | B13: Li La LiNuS | C13: 125292266 | D13: =VLOOKUP(B13,TS!$B$2:$C$104,2,0) -> R3 | E13: R3 | F13: =IF(D13<>E13,"Y","N") -> N
... A35: 34 | B35: azerty57 | C35: 86874424 | D35: =VLOOKUP(B35,TS!$B$2:$C$104,2,0) -> R2 | E35: R3 | F35: =IF(D35<>E35,"Y","N") -> Y
A36: 35 | B36: Kytrider | C36: 86530803 | D36: =VLOOKUP(B36,TS!$B$2:$C$104,2,0) -> R4 | E36: R4 | F36: N
A37: 36 | B37: sunny75 | C37: 85521444 | D37: =VLOOKUP(B37,TS!$B$2:$C$104,2,0) -> R3 | E37: R3 | F37: =IF(D37<>E37,"Y","N") -> N
A38: 37 | B38: fffeyz | C38: 85352470 | D38: =VLOOKUP(B38,TS!$B$2:$C$104,2,0) -> R3 | E38: R3 | F38: =IF(D38<>E38,"Y","N") -> N
A39: 38 | B39: feimel | C39: 85350125 | D39: =VLOOKUP(B39,TS!$B$2:$C$104,2,0) -> R3 | E39: R3 | F39: =IF(D39<>E39,"Y","N") -> N
A40: 39 | B40: Jacob Carter | C40: 83796421 | D40: =VLOOKUP(B40,TS!$B$2:$C$104,2,0) -> R3 | E40: R3 | F40: =IF(D40<>E40,"Y","N") -> N
A41: 40 | B41: K E R S Y | C41: 82223922 | D41: =VLOOKUP(B41,TS!$B$2:$C$104,2,0) -> R3 | E41: R3 | F41: =IF(D41<>E41,"Y","N") -> N
A42: 41 | B42: Christo30 | C42: 80913438 | D42: =VLOOKUP(B42,TS!$B$2:$C$104,2,0) -> R2 | E42: R3 | F42: =IF(D42<>E42,"Y","N") -> Y
A43: 42 | B43: Aenwe | C43: 80828058 | D43: =VLOOKUP(B43,TS!$B$2:$C$104,2,0) -> R3 | E43: R3 | F43: =IF(D43<>E43,"Y","N") -> N
A44: 43 | B44: Schlabberbacke | C44: 80403943 | D44: =VLOOKUP(B44,TS!$B$2:$C$104,2,0) -> R4 | E44: R4 | F44: =IF(D44<>E44,"Y","N") -> N
A45: 44 | B45: jukata | C45: 78956256 | D45: =VLOOKUP(B45,TS!$B$2:$C$104,2,0) -> R2 | E45: R3 | F45: =IF(D45<>E45,"Y","N") -> Y
A46: 45 | B46: Feivel D MauS | C46: 77161104 | D46: =VLOOKUP(B46,TS!$B$2:$C$104,2,0) -> R3 | E46: R3 | F46: =IF(D46<>E46,"Y","N") -> N
A47: 46 | B47: Katerina77 | C47: 76411972 | D47: =VLOOKUP(B47,TS!$B$2:$C$104,2,0) -> R2 | E47: R3 | F47: =IF(D47<>E47,"Y","N") -> Y
A48: 47 | B48: Tom12234455 | C48: 76136056 | D48: =VLOOKUP(B48,TS!$B$2:$C$104,2,0) -> R3 | E48: R3 | F48: =IF(D48<>E48,"Y","N") -> N
... A71: 70 | B71: MetauChopf | C71: 58598844 | D71: =VLOOKUP(B71,TS!$B$2:$C$104,2,0) -> R3 | E71: R3 | F71: =IF(D71<>E71,"Y","N") -> N
A72: 71 | B72: 케프 부인 | C72: 56800539 | D72: =VLOOKUP(B72,TS!$B$2:$C$104,2,0) -> R2 | E72: R3 | F72: N
A73: 72 | B73: Mac1902 | C73: 56567839 | D73: =VLOOKUP(B73,TS!$B$2:$C$104,2,0) -> R2 | E73: R3 | F73: =IF(D73<>E73,"Y","N") -> Y
A74: 73 | B74: Leijonamieli | C74: 56192603 | D74: =VLOOKUP(B74,TS!$B$2:$C$104,2,0) -> R2 | E74: R3 | F74: =IF(D74<>E74,"Y","N") -> Y
A75: 74 | B75: GaaGol | C75: 52806655 | D75: =VLOOKUP(B75,TS!$B$2:$C$104,2,0) -> R2 | E75: R2 | F75: =IF(D75<>E75,"Y","N") -> N
A76: 75 | B76: Lilien1999 | C76: 52363184 | D76: =VLOOKUP(B76,TS!$B$2:$C$104,2,0) -> R2 | E76: R2 | F76: =IF(D76<>E76,"Y","N") -> N
A77: 76 | B77: jobcenter FFM | C77: 51268680 | D77: =VLOOKUP(B77,TS!$B$2:$C$104,2,0) -> R3 | E77: R2 | F77: =IF(D77<>E77,"Y","N") -> Y
A78: 77 | B78: Xambash | C78: 51003173 | D78: =VLOOKUP(B78,TS!$B$2:$C$104,2,0) -> R2 | E78: R2 | F78: =IF(D78<>E78,"Y","N") -> N
A79: 78 | B79: EXITUS | C79: 50633326 | D79: =VLOOKUP(B79,TS!$B$2:$C$104,2,0) -> R2 | E79: R3 | F79: N | G79: R3
A80: 79 | B80: LatastrophenUlli | C80: 50233175 | D80: =VLOOKUP(B80,TS!$B$2:$C$104,2,0) -> R2 | E80: R2 | F80: =IF(D80<>E80,"Y","N") -> N
A81: 80 | B81: MG Mayo | C81: 48759812 | D81: =VLOOKUP(B81,TS!$B$2:$C$104,2,0) -> R2 | E81: R2 | F81: =IF(D81<>E81,"Y","N") -> N
A82: 81 | B82: ozzy5255 | C82: 47157316 | D82: =VLOOKUP(B82,TS!$B$2:$C$104,2,0) -> R3 | E82: R2 | F82: =IF(D82<>E82,"Y","N") -> Y
A83: 82 | B83: Himbeertony | C83: 45123012 | D83: =VLOOKUP(B83,TS!$B$2:$C$104,2,0) -> R3 | E83: R2 | F83: =IF(D83<>E83,"Y","N") -> Y
...

Sheet TS
A1: Rank | B1: Name | C1: Level | D1: Points
A2: 1 | B2: azerty57 | C2: R2 | D2: 100850
A3: 2 | B3: cappu97 | C3: R4 | D3: 82950
A4: 3 | B4: Bugab0o | C4: R3 | D4: 77500
A5: 4 | B5: Last Wolf Warrior | C5: R2 | D5: 72250
A6: 5 | B6: PHOENIX FOX | C6: R4 | D6: 65800
A7: 6 | B7: Svela17 | C7: R3 | D7: 65250
A8: 7 | B8: Queen from AZO | C8: R5 | D8: 63450
A9: 8 | B9: Smowy | C9: R4 | D9: 63300
A10: 9 | B10: Gordon Freimann | C10: R3 | D10: 62250
A11: 10 | B11: K E R S Y | C11: R3 | D11: 60750
A12: 11 | B12: Jónny666 | C12: R3 | D12: 60400
A13: 12 | B13: jukata | C13: R2 | D13: 58700
... A94: 93 | B94: R2DrehZwo | C94: R1 | D94: 0
