Workbook

Sheet Grenzen
B2: Sparwoche | C2: R2 | D2: 35
C3: R3 | D3: 45
B5: All in woche | C5: R2 | D5: 40
C6: R3 | D6: 55

Sheet VS
A1: Position | B1: Name | C1: Points | D1: Alt | E1: Neu | F1: Change | G1: Ausnahme
A2: 1 | B2: Bugab0o | C2: 208734015 | D2: =VLOOKUP(B2,TS!$B$2:$D$99,2,0) -> R3 | E2: R3 | F2: =IF(D2<>E2,"Y","N") -> N
A3: 2 | B3: Last Wolf Warrior | C3: 164292306 | D3: =VLOOKUP(B3,TS!$B$2:$D$99,2,0) -> R3 | E3: R3 | F3: =IF(D3<>E3,"Y","N") -> N
A4: 3 | B4: JSheridan | C4: 158596859 | D4: =VLOOKUP(B4,TS!$B$2:$D$99,2,0) -> R4 | E4: R4 | F4: =IF(D4<>E4,"Y","N") -> N
A5: 4 | B5: Svela17 | C5: 152745146 | D5: =VLOOKUP(B5,TS!$B$2:$D$99,2,0) -> R3 | E5: R3 | F5: =IF(D5<>E5,"Y","N") -> N
A6: 5 | B6: Fran171526 | C6: 149527588 | D6: =VLOOKUP(B6,TS!$B$2:$D$99,2,0) -> R4 | E6: R4 | F6: =IF(D6<>E6,"Y","N") -> N
A7: 6 | B7: supi pupi | C7: 143097807 | D7: =VLOOKUP(B7,TS!$B$2:$D$99,2,0) -> R4 | E7: R4 | F7: =IF(D7<>E7,"Y","N") -> N
A8: 7 | B8: Chrisiiii | C8: 141512282 | D8: =VLOOKUP(B8,TS!$B$2:$D$99,2,0) -> R3 | E8: R3 | F8: =IF(D8<>E8,"Y","N") -> N
A9: 8 | B9: Bogo und Pini | C9: 138043484 | D9: =VLOOKUP(B9,TS!$B$2:$D$99,2,0) -> R3 | E9: R3 | F9: =IF(D9<>E9,"Y","N") -> N
A10: 9 | B10: pizm8 ツ | C10: 137392792 | D10: =VLOOKUP(B10,TS!$B$2:$D$99,2,0) -> R4 | E10: R4 | F10: =IF(D10<>E10,"Y","N") -> N
A11: 10 | B11: Kotor47 | C11: 134636683 | D11: =VLOOKUP(B11,TS!$B$2:$D$99,2,0) -> R3 | E11: R3 | F11: =IF(D11<>E11,"Y","N") -> N
A12: 11 | B12: giMp | C12: 133448324 | D12: =VLOOKUP(B12,TS!$B$2:$D$99,2,0) -> R3 | E12: R3 | F12: =IF(D12<>E12,"Y","N") -> N
A13: 12 | B13: Giorgiotown | C13: 125291128 | D13: =VLOOKUP(B13,TS!$B$2:$D$99,2,0) -> R3 | E13: R3 | F13: =IF(D13<>E13,"Y","N") -> N
... A55: 54 | B55: MetauChopf | C55: 69607820 | D55: =VLOOKUP(B55,TS!$B$2:$D$99,2,0) -> R3 | E55: R3 | F55: =IF(D55<>E55,"Y","N") -> N
A56: 55 | B56: ToxicV9 | C56: 69554989 | D56: - | E56: - | F56: =IF(D56<>E56,"Y","N") -> N
A57: 56 | B57: sunny75 | C57: 69525125 | D57: =VLOOKUP(B57,TS!$B$2:$D$99,2,0) -> R3 | E57: R3 | F57: =IF(D57<>E57,"Y","N") -> N
A58: 57 | B58: fffeyz | C58: 67408514 | D58: =VLOOKUP(B58,TS!$B$2:$D$99,2,0) -> R2 | E58: R3 | F58: =IF(D58<>E58,"Y","N") -> Y
A59: 58 | B59: EXITUS | C59: 66730297 | D59: =VLOOKUP(B59,TS!$B$2:$D$99,2,0) -> R3 | E59: R3 | F59: =IF(D59<>E59,"Y","N") -> N
A60: 59 | B60: feimel | C60: 65030383 | D60: =VLOOKUP(B60,TS!$B$2:$D$99,2,0) -> R3 | E60: R3 | F60: =IF(D60<>E60,"Y","N") -> N
A61: 60 | B61: CalziferFire | C61: 63863426 | D61: =VLOOKUP(B61,TS!$B$2:$D$99,2,0) -> R3 | E61: R3 | F61: =IF(D61<>E61,"Y","N") -> N
A62: 61 | B62: Mischel89 | C62: 62685489 | D62: =VLOOKUP(B62,TS!$B$2:$D$99,2,0) -> R1 | E62: R3 | F62: =IF(D62<>E62,"Y","N") -> Y
A63: 62 | B63: waynowazza | C63: 61053696 | D63: =VLOOKUP(B63,TS!$B$2:$D$99,2,0) -> R2 | E63: R3 | F63: =IF(D63<>E63,"Y","N") -> Y
A64: 63 | B64: Tyskie 66 | C64: 60716292 | D64: =VLOOKUP(B64,TS!$B$2:$D$99,2,0) -> R3 | E64: R3 | F64: =IF(D64<>E64,"Y","N") -> N
A65: 64 | B65: تاجM | C65: 60193675 | D65: =VLOOKUP(B65,TS!$B$2:$D$99,2,0) -> R2 | E65: R3 | F65: =IF(D65<>E65,"Y","N") -> Y
A66: 65 | B66: Katerina77 | C66: 58763879 | D66: =VLOOKUP(B66,TS!$B$2:$D$99,2,0) -> R3 | E66: R3 | F66: =IF(D66<>E66,"Y","N") -> N
A67: 66 | B67: Itstheghoul | C67: 57736248 | D67: =VLOOKUP(B67,TS!$B$2:$D$99,2,0) -> R3 | E67: R3 | F67: =IF(D67<>E67,"Y","N") -> N
A68: 67 | B68: jobcenter FFM | C68: 56219825 | D68: =VLOOKUP(B68,TS!$B$2:$D$99,2,0) -> R2 | E68: R3 | F68: =IF(D68<>E68,"Y","N") -> Y
... A86: 85 | B86: Himbeertony | C86: 9960900 | D86: =VLOOKUP(B86,TS!$B$2:$D$99,2,0) -> R2 | E86: R1 | F86: =IF(D86<>E86,"Y","N") -> Y
A87: 86 | B87: Peridakles | C87: 36214 | D87: - | E87: - | F87: =IF(D87<>E87,"Y","N") -> N
A88: 0 | B88: Cichax0 | C88: 0 | D88: =VLOOKUP(B88,TS!$B$2:$D$99,2,0) -> R2 | E88: R2 | F88: =IF(D88<>E88,"Y","N") -> N | G88: neu
A89: 0 | B89: LunaLiya | C89: 0 | D89: =VLOOKUP(B89,TS!$B$2:$D$99,2,0) -> R2 | E89: R2 | F89: =IF(D89<>E89,"Y","N") -> N | G89: neu
A90: 0 | B90: PHILAES | C90: 0 | D90: =VLOOKUP(B90,TS!$B$2:$D$99,2,0) -> R2 | E90: R2 | F90: =IF(D90<>E90,"Y","N") -> N | G90: neu
A91: 0 | B91: 111Dave111 | C91: 0 | D91: =VLOOKUP(B91,TS!$B$2:$D$99,2,0) -> R2 | E91: R2 | F91: =IF(D91<>E91,"Y","N") -> N | G91: neu
A92: 0 | B92: Babakuji | C92: 0 | D92: =VLOOKUP(B92,TS!$B$2:$D$99,2,0) -> R2 | E92: R2 | F92: =IF(D92<>E92,"Y","N") -> N | G92: neu
A93: 0 | B93: Adhd9 | C93: 0 | D93: =VLOOKUP(B93,TS!$B$2:$D$99,2,0) -> R3 | E93: R2 | F93: =IF(D93<>E93,"Y","N") -> Y | G93: neu
A94: 0 | B94: Moooolah | C94: 0 | D94: =VLOOKUP(B94,TS!$B$2:$D$99,2,0) -> R2 | E94: R2 | F94: =IF(D94<>E94,"Y","N") -> N | G94: neu
A95: 0 | B95: Adám | C95: 0 | D95: =VLOOKUP(B95,TS!$B$2:$D$99,2,0) -> R3 | E95: R2 | F95: =IF(D95<>E95,"Y","N") -> Y | G95: neu
A96: 0 | B96: JSnoopy | C96: 0 | D96: =VLOOKUP(B96,TS!$B$2:$D$99,2,0) -> R2 | E96: R2 | F96: =IF(D96<>E96,"Y","N") -> N | G96: neu
A97: 0 | B97: Fluffy | C97: 0 | D97: =VLOOKUP(B97,TS!$B$2:$D$99,2,0) -> R2 | E97: R2 | F97: =IF(D97<>E97,"Y","N") -> N | G97: neu
A98: 0 | B98: Mudin364 | C98: 0 | D98: =VLOOKUP(B98,TS!$B$2:$D$99,2,0) -> R2 | E98: R2 | F98: =IF(D98<>E98,"Y","N") -> N | G98: neu
...

Sheet TS
A1: position | B1: name | C1: rank | D1: points | E1: vs
A2: 1 | B2: azerty57 | C2: R3 | D2: 102000 | E2: =VLOOKUP(B2,VS!B:B,1,0) -> azerty57
A3: 2 | B3: Bugab0o | C3: R3 | D3: 79900 | E3: =VLOOKUP(B3,VS!B:B,1,0) -> Bugab0o
A4: 3 | B4: cappu97 | C4: R4 | D4: 74500 | E4: =VLOOKUP(B4,VS!B:B,1,0) -> cappu97
A5: 4 | B5: Anakín | C5: R3 | D5: 71000 | E5: =VLOOKUP(B5,VS!B:B,1,0) -> Anakín
A6: 5 | B6: Svela17 | C6: R3 | D6: 68500 | E6: =VLOOKUP(B6,VS!B:B,1,0) -> Svela17
A7: 6 | B7: waynowazza | C7: R2 | D7: 67600 | E7: =VLOOKUP(B7,VS!B:B,1,0) -> waynowazza
A8: 7 | B8: Queeniiiiii | C8: R5 | D8: 66600 | E8: =VLOOKUP(B8,VS!B:B,1,0) -> Queeniiiiii
A9: 8 | B9: ECSI | C9: R3 | D9: 65150 | E9: =VLOOKUP(B9,VS!B:B,1,0) -> ECSI
A10: 9 | B10: JSheridan | C10: R4 | D10: 63750 | E10: =VLOOKUP(B10,VS!B:B,1,0) -> JSheridan
A11: 10 | B11: Last Wolf Warrior | C11: R3 | D11: 63350 | E11: =VLOOKUP(B11,VS!B:B,1,0) -> Last Wolf Warrior
A12: 11 | B12: jukata | C12: R3 | D12: 63150 | E12: =VLOOKUP(B12,VS!B:B,1,0) -> jukata
A13: 12 | B13: Bogo und Pini | C13: R3 | D13: 63050 | E13: =VLOOKUP(B13,VS!B:B,1,0) -> Bogo und Pini
... A99: 98 | B99: Skywölkchen | C99: R2 | D99: 0 | E99: =VLOOKUP(B99,VS!B:B,1,0) -> Skywölkchen
